Workbook
Name Scenario: 'Scenarios'!$C$4
Name Revenue_2026E: 'Income Statement'!$G$7
Name NI_Parent_2026E: 'Income Statement'!$G$68
Name EPS_2026E: 'Income Statement'!$G$75
Name UFCF_2026E: 'DCF Inputs'!$G$15
Name Revenue_2027E: 'Income Statement'!$H$7
Name NI_Parent_2027E: 'Income Statement'!$H$68
Name EPS_2027E: 'Income Statement'!$H$75
Name UFCF_2027E: 'DCF Inputs'!$H$15
Name Revenue_2028E: 'Income Statement'!$I$7
Name NI_Parent_2028E: 'Income Statement'!$I$68
Name EPS_2028E: 'Income Statement'!$I$75
Name UFCF_2028E: 'DCF Inputs'!$I$15
Name Revenue_2029E: 'Income Statement'!$J$7
Name NI_Parent_2029E: 'Income Statement'!$J$68
Name EPS_2029E: 'Income Statement'!$J$75
Name UFCF_2029E: 'DCF Inputs'!$J$15
Name Revenue_2030E: 'Income Statement'!$K$7
Name NI_Parent_2030E: 'Income Statement'!$K$68
Name EPS_2030E: 'Income Statement'!$K$75
Name UFCF_2030E: 'DCF Inputs'!$K$15
Name NetDebt_2025A: 'DCF Inputs'!$F$21
Name Minority_BV_2025A: 'DCF Inputs'!$F$22
Name Shares: 'DCF Inputs'!$F$26
Name Price: 'DCF Inputs'!$F$30

Sheet Cover
A1: 中国核电（601985.SH）财务模型
A2: Financial Model — China National Nuclear Power Co., Ltd.
A3: 编制日期 | B3: 2026-10-02（initiating-coverage · Task 2）
A4: 当前情景 | B4: =Scenarios!D4 -> Base 基准
A5: 单位 | B5: 亿元人民币（另有注明除外）；电量 亿千瓦时；装机 万千瓦；电价 元/千瓦时（含增值税）
A6: 历史期 | B6: 2022A–2025A：2023 年年报（2022、2023）与 2025 年年报（2024、2025）合并报表；2026H1A 见利润表 M 列
A7: 预测期 | B7: 2026E–2030E：公式驱动；所有情景假设在 Scenarios 工作表（C4 切换），其余假设以蓝色输入列示在各表行内
A8: 颜色规范 | B8: 蓝色=硬编码输入/历史数据；黑色=公式；绿色=跨表链接；灰底=历史期
A9: 平衡机制 | B9: 长期借款为平衡项：净借款使期末现金=目标现金（收入×18%）；利息按期初有息负债计提，无循环引用
A10: 工作表 | B10: Task 2：Revenue Model｜Income Statement｜Cash Flow｜Balance Sheet｜Scenarios｜DCF Inputs；Task 3：DCF｜Sensitivity｜Comps｜Precedents｜Valuation Summary；Checks｜Hist_Data
A11: 目标价（元，12 个月） | B11: ='Valuation Summary'!C12 -> 8
A12: 评级 | B12: ='Valuation Summary'!C17 -> 减持 SELL
A13: 数据来源 | B13: CNNP_601985/source/：CNNP_2023_年报.pdf、CNNP_2025_年报.pdf、CNNP_2026H1_半年报.pdf；行业及股价数据见 Task 1 研究文档
A14: 重要局限 | B14: ①2022–23A 与 2024–25A 成本分析表口径不同；②核电/新能源分产品收入为上网电量×综合电价推算；③2024 年末风光装机拆分为估算；④分地区 2022A/2024A 按同比倒推；⑤新机组造价按预算/容量，庄河、金七门 3–4 号为估计
A15: 校验 | B15: =IF(Checks!C18,"全部校验通过 ✔","存在未通过校验 ✘ — 见 Checks") -> 全部校验通过 ✔

Sheet Revenue Model
A1: 收入模型 Revenue Model — 中国核电 601985.SH
A2: 单位：亿元人民币（另有注明除外）｜蓝色=硬编码输入 黑色=公式 绿色=跨表链接｜A=实际 E=预测
A3: 项目 / Line item | B3: 单位 | C3: 2022 | D3: 2023 | E3: 2024 | F3: 2025 | G3: 2026 | H3: 2027 | I3: 2028 | J3: 2029 | K3: 2030 | L3: 来源 / 说明
A6: A. 核电机组投产计划 Nuclear pipeline（年报 2025 第 17、33 页；2026 半年报第 11 页）
A7: 机组 Unit | B7: 区域 | C7: 容量 万kW | D7: 计划商运年 | E7: 情景商运年 | F7: 单位造价 元/kW | G7: ← 各年平均装机贡献（万千瓦） 2026E–2030E → | L7: 预算/说明
A8: 田湾 7 号 | B8: 华东 | C8: 126.5 | D8: 2026 | E8: =D8+'Scenarios'!$G$24 -> 2026 | F8: 20011 | G8: =IF(G$3>$E8,$C8,IF(G$3=$E8,$C8*'Scenarios'!G$30,0)) -> 50.6 | H8: =IF(H$3>$E8,$C8,IF(H$3=$E8,$C8*'Scenarios'!H$30,0)) -> 126.5 | I8: =IF(I$3>$E8,$C8,IF(I$3=$E8,$C8*'Scenarios'!I$30,0)) -> 126.5 | J8: =IF(J$3>$E8,$C8,IF(J$3=$E8,$C8*'Scenarios'!J$30,0)) -> 126.5 | K8: =IF(K$3>$E8,$C8,IF(K$3=$E8,$C8*'Scenarios'!K$30,0)) -> 126.5 | L8: 田湾 7、8 号预算 506.29 亿；2026-08 首次装料
A9: 海南小堆 玲龙一号 | B9: 华南 | C9: 12.5 | D9: 2026 | E9: =D9+'Scenarios'!$G$24 -> 2026 | F9: 30120 | G9: =IF(G$3>$E9,$C9,IF(G$3=$E9,$C9*'Scenarios'!G$30,0)) -> 5 | H9: =IF(H$3>$E9,$C9,IF(H$3=$E9,$C9*'Scenarios'!H$30,0)) -> 12.5 | I9: =IF(I$3>$E9,$C9,IF(I$3=$E9,$C9*'Scenarios'!I$30,0)) -> 12.5 | J9: =IF(J$3>$E9,$C9,IF(J$3=$E9,$C9*'Scenarios'!J$30,0)) -> 12.5 | K9: =IF(K$3>$E9,$C9,IF(K$3=$E9,$C9*'Scenarios'!K$30,0)) -> 12.5 | L9: 预算 37.65 亿；全球首个陆上商用 SMR
A10: 徐大堡 3 号 | B10: 东北 | C10: 127.4 | D10: 2027 | E10: =D10+'Scenarios'!$G$24 -> 2027 | F10: 20544 | G10: =IF(G$3>$E10,$C10,IF(G$3=$E10,$C10*'Scenarios'!G$30,0)) -> 0 | H10: =IF(H$3>$E10,$C10,IF(H$3=$E10,$C10*'Scenarios'!H$30,0)) -> 50.96 | I10: =IF(I$3>$E10,$C10,IF(I$3=$E10,$C10*'Scenarios'!I$30,0)) -> 127.4 | J10: =IF(J$3>$E10,$C10,IF(J$3=$E10,$C10*'Scenarios'!J$30,0)) -> 127.4 | K10: =IF(K$3>$E10,$C10,IF(K$3=$E10,$C10*'Scenarios'!K$30,0)) -> 127.4 | L10: 徐大堡 3、4 号预算 523.47 亿
A11: 三门 3 号 | B11: 华东 | C11: 125.1 | D11: 2027 | E11: =D11+'Scenarios'!$G$24 -> 2027 | F11: 18455 | G11: =IF(G$3>$E11,$C11,IF(G$3=$E11,$C11*'Scenarios'!G$30,0)) -> 0 | H11: =IF(H$3>$E11,$C11,IF(H$3=$E11,$C11*'Scenarios'!H$30,0)) -> 50.04 | I11: =IF(I$3>$E11,$C11,IF(I$3=$E11,$C11*'Scenarios'!I$30,0)) -> 125.1 | J11: =IF(J$3>$E11,$C11,IF(J$3=$E11,$C11*'Scenarios'!J$30,0)) -> 125.1 | K11: =IF(K$3>$E11,$C11,IF(K$3=$E11,$C11*'Scenarios'!K$30,0)) -> 125.1 | L11: 三门 3、4 号预算 461.75 亿
A12: 田湾 8 号 | B12: 华东 | C12: 126.5 | D12: 2027 | E12: =D12+'Scenarios'!$G$24 -> 2027 | F12: 20011 | G12: =IF(G$3>$E12,$C12,IF(G$3=$E12,$C12*'Scenarios'!G$30,0)) -> 0 | H12: =IF(H$3>$E12,$C12,IF(H$3=$E12,$C12*'Scenarios'!H$30,0)) -> 50.6 | I12: =IF(I$3>$E12,$C12,IF(I$3=$E12,$C12*'Scenarios'!I$30,0)) -> 126.5 | J12: =IF(J$3>$E12,$C12,IF(J$3=$E12,$C12*'Scenarios'!J$30,0)) -> 126.5 | K12: =IF(K$3>$E12,$C12,IF(K$3=$E12,$C12*'Scenarios'!K$30,0)) -> 126.5 | L12: 2026H1 启动冷试
A13: 三门 4 号 | B13: 华东 | C13: 125.1 | D13: 2027 | E13: =D13+'Scenarios'!$G$24 -> 2027 | F13: 18455 | G13: =IF(G$3>$E13,$C13,IF(G$3=$E13,$C13*'Scenarios'!G$30,0)) -> 0 | H13: =IF(H$3>$E13,$C13,IF(H$3=$E13,$C13*'Scenarios'!H$30,0)) -> 50.04 | I13: =IF(I$3>$E13,$C13,IF(I$3=$E13,$C13*'Scenarios'!I$30,0)) -> 125.1 | J13: =IF(J$3>$E13,$C13,IF(J$3=$E13,$C13*'Scenarios'!J$30,0)) -> 125.1 | K13: =IF(K$3>$E13,$C13,IF(K$3=$E13,$C13*'Scenarios'!K$30,0)) -> 125.1
A14: 徐大堡 1 号 | B14: 东北 | C14: 129.1 | D14: 2028 | E14: =D14+'Scenarios'!$G$24 -> 2028 | F14: 16339 | G14: =IF(G$3>$E14,$C14,IF(G$3=$E14,$C14*'Scenarios'!G$30,0)) -> 0 | H14: =IF(H$3>$E14,$C14,IF(H$3=$E14,$C14*'Scenarios'!H$30,0)) -> 0 | I14: =IF(I$3>$E14,$C14,IF(I$3=$E14,$C14*'Scenarios'!I$30,0)) -> 51.64 | J14: =IF(J$3>$E14,$C14,IF(J$3=$E14,$C14*'Scenarios'!J$30,0)) -> 129.1 | K14: =IF(K$3>$E14,$C14,IF(K$3=$E14,$C14*'Scenarios'!K$30,0)) -> 129.1 | L14: 徐大堡 1、2 号预算 421.88 亿
A15: 徐大堡 4 号 | B15: 东北 | C15: 127.4 | D15: 2028 | E15: =D15+'Scenarios'!$G$24 -> 2028 | F15: 20544 | G15: =IF(G$3>$E15,$C15,IF(G$3=$E15,$C15*'Scenarios'!G$30,0)) -> 0 | H15: =IF(H$3>$E15,$C15,IF(H$3=$E15,$C15*'Scenarios'!H$30,0)) -> 0 | I15: =IF(I$3>$E15,$C15,IF(I$3=$E15,$C15*'Scenarios'!I$30,0)) -> 50.96 | J15: =IF(J$3>$E15,$C15,IF(J$3=$E15,$C15*'Scenarios'!J$30,0)) -> 127.4 | K15: =IF(K$3>$E15,$C15,IF(K$3=$E15,$C15*'Scenarios'!K$30,0)) -> 127.4
A16: 漳州 3 号 | B16: 华东 | C16: 121.2 | D16: 2029 | E16: =D16+'Scenarios'!$G$24 -> 2029 | F16: 16362 | G16: =IF(G$3>$E16,$C16,IF(G$3=$E16,$C16*'Scenarios'!G$30,0)) -> 0 | H16: =IF(H$3>$E16,$C16,IF(H$3=$E16,$C16*'Scenarios'!H$30,0)) -> 0 | I16: =IF(I$3>$E16,$C16,IF(I$3=$E16,$C16*'Scenarios'!I$30,0)) -> 0 | J16: =IF(J$3>$E16,$C16,IF(J$3=$E16,$C16*'Scenarios'!J$30,0)) -> 48.48 | K16: =IF(K$3>$E16,$C16,IF(K$3=$E16,$C16*'Scenarios'!K$30,0)) -> 121.2 | L16: 漳州 3、4 号预算 396.62 亿
A17: 徐大堡 2 号 | B17: 东北 | C17: 129.1 | D17: 2029 | E17: =D17+'Scenarios'!$G$24 -> 2029 | F17: 16339 | G17: =IF(G$3>$E17,$C17,IF(G$3=$E17,$C17*'Scenarios'!G$30,0)) -> 0 | H17: =IF(H$3>$E17,$C17,IF(H$3=$E17,$C17*'Scenarios'!H$30,0)) -> 0 | I17: =IF(I$3>$E17,$C17,IF(I$3=$E17,$C17*'Scenarios'!I$30,0)) -> 0 | J17: =IF(J$3>$E17,$C17,IF(J$3=$E17,$C17*'Scenarios'!J$30,0)) -> 51.64 | K17: =IF(K$3>$E17,$C17,IF(K$3=$E17,$C17*'Scenarios'!K$30,0)) -> 129.1
A18: 漳州 4 号 | B18: 华东 | C18: 121.2 | D18: 2029 | E18: =D18+'Scenarios'!$G$24 -> 2029 | F18: 16362 | G18: =IF(G$3>$E18,$C18,IF(G$3=$E18,$C18*'Scenarios'!G$30,0)) -> 0 | H18: =IF(H$3>$E18,$C18,IF(H$3=$E18,$C18*'Scenarios'!H$30,0)) -> 0 | I18: =IF(I$3>$E18,$C18,IF(I$3=$E18,$C18*'Scenarios'!I$30,0)) -> 0 | J18: =IF(J$3>$E18,$C18,IF(J$3=$E18,$C18*'Scenarios'!J$30,0)) -> 48.48 | K18: =IF(K$3>$E18,$C18,IF(K$3=$E18,$C18*'Scenarios'!K$30,0)) -> 121.2
A19: 金七门 1 号 | B19: 华东 | C19: 121.5 | D19: 2030 | E19: =D19+'Scenarios'!$G$24 -> 2030 | F19: 18343 | G19: =IF(G$3>$E19,$C19,IF(G$3=$E19,$C19*'Scenarios'!G$30,0)) -> 0 | H19: =IF(H$3>$E19,$C19,IF(H$3=$E19,$C19*'Scenarios'!H$30,0)) -> 0 | I19: =IF(I$3>$E19,$C19,IF(I$3=$E19,$C19*'Scenarios'!I$30,0)) -> 0 | J19: =IF(J$3>$E19,$C19,IF(J$3=$E19,$C19*'Scenarios'!J$30,0)) -> 0 | K19: =IF(K$3>$E19,$C19,IF(K$3=$E19,$C19*'Scenarios'!K$30,0)) -> 48.6 | L19: 金七门 1、2 号预算 445.74 亿
A20: 徐圩 1 号 | B20: 华东 | C20: 122.2 | D20: 2031 | E20: =D20+'Scenarios'!$G$24 -> 2031 | F20: 23183 | G20: =IF(G$3>$E20,$C20,IF(G$3=$E20,$C20*'Scenarios'!G$30,0)) -> 0 | H20: =IF(H$3>$E20,$C20,IF(H$3=$E20,$C20*'Scenarios'!H$30,0)) -> 0 | I20: =IF(I$3>$E20,$C20,IF(I$3=$E20,$C20*'Scenarios'!I$30,0)) -> 0 | J20: =IF(J$3>$E20,$C20,IF(J$3=$E20,$C20*'Scenarios'!J$30,0)) -> 0 | K20: =IF(K$3>$E20,$C20,IF(K$3=$E20,$C20*'Scenarios'!K$30,0)) -> 0 | L20: 徐圩一期预算 719.61 亿（含高温堆，310.4 万kW）
A21: 金七门 2 号 | B21: 华东 | C21: 121.5 | D21: 2031 | E21: =D21+'Scenarios'!$G$24 -> 2031 | F21: 18343 | G21: =IF(G$3>$E21,$C21,IF(G$3=$E21,$C21*'Scenarios'!G$30,0)) -> 0 | H21: =IF(H$3>$E21,$C21,IF(H$3=$E21,$C21*'Scenarios'!H$30,0)) -> 0 | I21: =IF(I$3>$E21,$C21,IF(I$3=$E21,$C21*'Scenarios'!I$30,0)) -> 0 | J21: =IF(J$3>$E21,$C21,IF(J$3=$E21,$C21*'Scenarios'!J$30,0)) -> 0 | K21: =IF(K$3>$E21,$C21,IF(K$3=$E21,$C21*'Scenarios'!K$30,0)) -> 0 | L21: 2026-04 FCD；计划商运年为作者估计
A22: 三门 6 号 | B22: 华东 | C22: 121.5 | D22: 2031 | E22: =D22+'Scenarios'!$G$24 -> 2031 | F22: 16675 | G22: =IF(G$3>$E22,$C22,IF(G$3=$E22,$C22*'Scenarios'!G$30,0)) -> 0 | H22: =IF(H$3>$E22,$C22,IF(H$3=$E22,$C22*'Scenarios'!H$30,0)) -> 0 | I22: =IF(I$3>$E22,$C22,IF(I$3=$E22,$C22*'Scenarios'!I$30,0)) -> 0 | J22: =IF(J$3>$E22,$C22,IF(J$3=$E22,$C22*'Scenarios'!J$30,0)) -> 0 | K22: =IF(K$3>$E22,$C22,IF(K$3=$E22,$C22*'Scenarios'!K$30,0)) -> 0 | L22: 公司披露：计划 2031-10 建成
A23: 三门 5 号 | B23: 华东 | C23: 121.5 | D23: 2032 | E23: =D23+'Scenarios'!$G$24 -> 2032 | F23: 16675 | G23: =IF(G$3>$E23,$C23,IF(G$3=$E23,$C23*'Scenarios'!G$30,0)) -> 0 | H23: =IF(H$3>$E23,$C23,IF(H$3=$E23,$C23*'Scenarios'!H$30,0)) -> 0 | I23: =IF(I$3>$E23,$C23,IF(I$3=$E23,$C23*'Scenarios'!I$30,0)) -> 0 | J23: =IF(J$3>$E23,$C23,IF(J$3=$E23,$C23*'Scenarios'!J$30,0)) -> 0 | K23: =IF(K$3>$E23,$C23,IF(K$3=$E23,$C23*'Scenarios'!K$30,0)) -> 0 | L23: 公司披露：计划 2032-08 建成
A24: 徐圩 2 号 + 高温堆 | B24: 华东 | C24: 188.2 | D24: 2032 | E24: =D24+'Scenarios'!$G$24 -> 2032 | F24: 23183 | G24: =IF(G$3>$E24,$C24,IF(G$3=$E24,$C24*'Scenarios'!G$30,0)) -> 0 | H24: =IF(H$3>$E24,$C24,IF(H$3=$E24,$C24*'Scenarios'!H$30,0)) -> 0 | I24: =IF(I$3>$E24,$C24,IF(I$3=$E24,$C24*'Scenarios'!I$30,0)) -> 0 | J24: =IF(J$3>$E24,$C24,IF(J$3=$E24,$C24*'Scenarios'!J$30,0)) -> 0 | K24: =IF(K$3>$E24,$C24,IF(K$3=$E24,$C24*'Scenarios'!K$30,0)) -> 0 | L24: 计划商运年为作者估计
A25: 庄河 1 号 | B25: 东北 | C25: 125 | D25: 2032 | E25: =D25+'Scenarios'!$G$24 -> 2032 | F25: 18000 | G25: =IF(G$3>$E25,$C25,IF(G$3=$E25,$C25*'Scenarios'!G$30,0)) -> 0 | H25: =IF(H$3>$E25,$C25,IF(H$3=$E25,$C25*'Scenarios'!H$30,0)) -> 0 | I25: =IF(I$3>$E25,$C25,IF(I$3=$E25,$C25*'Scenarios'!I$30,0)) -> 0 | J25: =IF(J$3>$E25,$C25,IF(J$3=$E25,$C25*'Scenarios'!J$30,0)) -> 0 | K25: =IF(K$3>$E25,$C25,IF(K$3=$E25,$C25*'Scenarios'!K$30,0)) -> 0 | L25: 2026-07-31 核准；造价、商运年为作者估计
A26: 庄河 2 号 | B26: 东北 | C26: 125 | D26: 2033 | E26: =D26+'Scenarios'!$G$24 -> 2033 | F26: 18000 | G26: =IF(G$3>$E26,$C26,IF(G$3=$E26,$C26*'Scenarios'!G$30,0)) -> 0 | H26: =IF(H$3>$E26,$C26,IF(H$3=$E26,$C26*'Scenarios'!H$30,0)) -> 0 | I26: =IF(I$3>$E26,$C26,IF(I$3=$E26,$C26*'Scenarios'!I$30,0)) -> 0 | J26: =IF(J$3>$E26,$C26,IF(J$3=$E26,$C26*'Scenarios'!J$30,0)) -> 0 | K26: =IF(K$3>$E26,$C26,IF(K$3=$E26,$C26*'Scenarios'!K$30,0)) -> 0
A27: 金七门 3 号 | B27: 华东 | C27: 123 | D27: 2032 | E27: =D27+'Scenarios'!$G$24 -> 2032 | F27: 18000 | G27: =IF(G$3>$E27,$C27,IF(G$3=$E27,$C27*'Scenarios'!G$30,0)) -> 0 | H27: =IF(H$3>$E27,$C27,IF(H$3=$E27,$C27*'Scenarios'!H$30,0)) -> 0 | I27: =IF(I$3>$E27,$C27,IF(I$3=$E27,$C27*'Scenarios'!I$30,0)) -> 0 | J27: =IF(J$3>$E27,$C27,IF(J$3=$E27,$C27*'Scenarios'!J$30,0)) -> 0 | K27: =IF(K$3>$E27,$C27,IF(K$3=$E27,$C27*'Scenarios'!K$30,0)) -> 0 | L27: 2026-07-31 核准；造价、商运年为作者估计
A28: 金七门 4 号 | B28: 华东 | C28: 123 | D28: 2033 | E28: =D28+'Scenarios'!$G$24 -> 2033 | F28: 18000 | G28: =IF(G$3>$E28,$C28,IF(G$3=$E28,$C28*'Scenarios'!G$30,0)) -> 0 | H28: =IF(H$3>$E28,$C28,IF(H$3=$E28,$C28*'Scenarios'!H$30,0)) -> 0 | I28: =IF(I$3>$E28,$C28,IF(I$3=$E28,$C28*'Scenarios'!I$30,0)) -> 0 | J28: =IF(J$3>$E28,$C28,IF(J$3=$E28,$C28*'Scenarios'!J$30,0)) -> 0 | K28: =IF(K$3>$E28,$C28,IF(K$3=$E28,$C28*'Scenarios'!K$30,0)) -> 0
A29: 在建及核准待建合计（22 台） | B29: 万千瓦 | C29: =SUM(C8:C28) -> 2563.5 | G29: =SUM(G8:G28) -> 55.6 | H29: =SUM(H8:H28) -> 340.64 | I29: =SUM(I8:I28) -> 745.7 | J29: =SUM(J8:J28) -> 1048.2 | K29: =SUM(K8:K28) -> 1319.7 | L29: 校验：应等于 2,563.50 万千瓦（2026 半年报披露日口径）
A30: 新机组年末在运容量 | B30: 万千瓦 | G30: =SUMPRODUCT(($E$8:$E$28<=G$3)*$C$8:$C$28) -> 139 | H30: =SUMPRODUCT(($E$8:$E$28<=H$3)*$C$8:$C$28) -> 643.1 | I30: =SUMPRODUCT(($E$8:$E$28<=I$3)*$C$8:$C$28) -> 899.6 | J30: =SUMPRODUCT(($E$8:$E$28<=J$3)*$C$8:$C$28) -> 1271.1 | K30: =SUMPRODUCT(($E$8:$E$28<=K$3)*$C$8:$C$28) -> 1392.6
A31: 新机组投产转固金额（容量×单位造价） | B31: 亿元 | G31: =SUMPRODUCT(($E$8:$E$28=G$3)*$C$8:$C$28*$F$8:$F$28)/10000 -> 290.78915 | H31: =SUMPRODUCT(($E$8:$E$28=H$3)*$C$8:$C$28*$F$8:$F$28)/10000 -> 976.61381 | I31: =SUMPRODUCT(($E$8:$E$28=I$3)*$C$8:$C$28*$F$8:$F$28)/10000 -> 472.66705 | J31: =SUMPRODUCT(($E$8:$E$28=J$3)*$C$8:$C$28*$F$8:$F$28)/10000 -> 607.55137 | K31: =SUMPRODUCT(($E$8:$E$28=K$3)*$C$8:$C$28*$F$8:$F$28)/10000 -> 222.86745 | L31: 链接 Balance Sheet 在建工程→固定资产
A33: B. 核电经营数据 Nuclear operations
A34: 秦山基地（含方家山，9台） 装机 | B34: 万千瓦 | D34: 666.4 | E34: 666.4 | F34: 670.2 | G34: 670.2 | H34: 670.2 | I34: 670.2 | J34: 670.2 | K34: 670.2 | L34: 存量机组装机（年报 2025 第 33 页；秦二厂 2 号 2025 年增容至 70.8 万kW）
A35: 田湾 1–6 号 装机 | B35: 万千瓦 | D35: 660.8 | E35: 660.8 | F35: 660.8 | G35: 660.8 | H35: 660.8 | I35: 660.8 | J35: 660.8 | K35: 660.8
A36: 福清 1–6 号 装机 | B36: 万千瓦 | D36: 667.8 | E36: 667.8 | F36: 667.8 | G36: 667.8 | H36: 667.8 | I36: 667.8 | J36: 667.8 | K36: 667.8
A37: 三门 1–2 号（AP1000） 装机 | B37: 万千瓦 | D37: 250 | E37: 250 | F37: 250 | G37: 250 | H37: 250 | I37: 250 | J37: 250 | K37: 250
A38: 海南昌江 1–2 号 装机 | B38: 万千瓦 | D38: 130 | E38: 130 | F38: 130 | G38: 130 | H38: 130 | I38: 130 | J38: 130 | K38: 130
A39: 漳州 1–2 号（华龙一号） 装机 | B39: 万千瓦 | D39: 0 | E39: 0 | F39: 121.2 | G39: 242.4 | H39: 242.4 | I39: 242.4 | J39: 242.4 | K39: 242.4
A40: 存量机组装机合计 | B40: 万千瓦 | D40: =SUM(D34:D39) -> 2375 | E40: =SUM(E34:E39) -> 2375 | F40: =SUM(F34:F39) -> 2500 | G40: =SUM(G34:G39) -> 2621.2 | H40: =SUM(H34:H39) -> 2621.2 | I40: =SUM(I34:I39) -> 2621.2 | J40: =SUM(J34:J39) -> 2621.2 | K40: =SUM(K34:K39) -> 2621.2
A41: 核电控股在运装机（年末） | B41: 万千瓦 | C41: 2375 | D41: 2375 | E41: 2375 | F41: 2500 | G41: =G40+G30 -> 2760.2 | H41: =H40+H30 -> 3264.3 | I41: =I40+I30 -> 3520.8 | J41: =J40+J30 -> 3892.3 | K41: =K40+K30 -> 4013.8 | L41: 2025A 2,500 万kW（26 台）；2026-01-01 漳州 2 号商运后 2,621.2 万kW
A42: 存量机组利用小时（情景） | B42: 小时 | D42: 7852 | E42: 7710 | F42: 8038 | G42: ='Scenarios'!G18 -> 7650 | H42: ='Scenarios'!H18 -> 7950 | I42: ='Scenarios'!I18 -> 7950 | J42: ='Scenarios'!J18 -> 7950 | K42: ='Scenarios'!K18 -> 7950 | L42: 历史=公司平均利用小时（年报发电效率表）
A43: 秦山基地（含方家山，9台） 发电量 | B43: 亿kWh | D43: 555.89675 | E43: 547.46205 | F43: 538.89202 | G43: =G34*G42/10000 -> 512.703 | H43: =H34*H42/10000 -> 532.809 | I43: =I34*I42/10000 -> 532.809 | J43: =J34*J42/10000 -> 532.809 | K43: =K34*K42/10000 -> 532.809 | L43: 历史=Σ机组容量×利用小时（推算）；预测装机 670.2 万kW
...

Sheet Income Statement
A1: 利润表 Income Statement（合并口径）
A2: 单位：亿元人民币（另有注明除外）｜蓝色=硬编码输入 黑色=公式 绿色=跨表链接｜A=实际 E=预测
A3: 项目 / Line item | B3: 单位 | C3: 2022 | D3: 2023 | E3: 2024 | F3: 2025 | G3: 2026 | H3: 2027 | I3: 2028 | J3: 2029 | K3: 2030 | L3: 来源 / 说明 | M3: 2026H1A | N3: H1/2026E
A6: 收入 Revenue
A7: 营业收入 Operating revenue | B7: 亿元 | C7: 712.85601 | D7: 749.5718 | E7: 772.72059 | F7: 820.75495 | G7: ='Revenue Model'!G100 -> 807.42717 | H7: ='Revenue Model'!H100 -> 908.71479 | I7: ='Revenue Model'!I100 -> 1014.6739 | J7: ='Revenue Model'!J100 -> 1096.1235 | K7: ='Revenue Model'!K100 -> 1172.2766 | L7: 历史：年报合并利润表；预测：Revenue Model | M7: 383.97892 | N7: =IFERROR(M7/G7,"") -> 0.47555859
A8: 同比 YoY | B8: % | D8: =D7/C7-1 -> 0.051505204 | E8: =E7/D7-1 -> 0.030882675 | F8: =F7/E7-1 -> 0.06216266 | G8: =G7/F7-1 -> -0.016238441 | H8: =H7/G7-1 -> 0.12544489 | I8: =I7/H7-1 -> 0.11660327 | J8: =J7/I7-1 -> 0.080271703 | K8: =K7/J7-1 -> 0.069474913
A9: 其中：核电 | B9: 亿元 | E9: ='Revenue Model'!E91 -> 629.11527 | F9: ='Revenue Model'!F91 -> 654.47225 | G9: ='Revenue Model'!G91 -> 640.81771 | H9: ='Revenue Model'!H91 -> 732.96277 | I9: ='Revenue Model'!I91 -> 830.98649 | J9: ='Revenue Model'!J91 -> 905.64668 | K9: ='Revenue Model'!K91 -> 972.65575
A10: 其中：新能源 | B10: 亿元 | E10: ='Revenue Model'!E95 -> 121.48902 | F10: ='Revenue Model'!F95 -> 141.68389 | G10: ='Revenue Model'!G95 -> 140.84776 | H10: ='Revenue Model'!H95 -> 148.70223 | I10: ='Revenue Model'!I95 -> 155.28513 | J10: ='Revenue Model'!J95 -> 160.65443 | K10: ='Revenue Model'!K95 -> 168.30732
A11: 其中：其他业务 | B11: 亿元 | C11: ='Revenue Model'!C99 -> 13.426008 | D11: ='Revenue Model'!D99 -> 16.911803 | E11: ='Revenue Model'!E99 -> 22.116294 | F11: ='Revenue Model'!F99 -> 24.534952 | G11: ='Revenue Model'!G99 -> 25.7617 | H11: ='Revenue Model'!H99 -> 27.049785 | I11: ='Revenue Model'!I99 -> 28.402274 | J11: ='Revenue Model'!J99 -> 29.822388 | K11: ='Revenue Model'!K99 -> 31.313507
A13: 营业成本驱动 COGS drivers（成本分析表口径）
A14: 核燃料单位成本 | B14: 元/kWh | E14: =E24/'Revenue Model'!E57 -> 0.041262437 | F14: =F24/'Revenue Model'!F57 -> 0.043348987 | G14: =F14*(1+'Scenarios'!G66) -> 0.045082946 | H14: =G14*(1+'Scenarios'!H66) -> 0.046886264 | I14: =H14*(1+'Scenarios'!I66) -> 0.048761715 | J14: =I14*(1+'Scenarios'!J66) -> 0.050712183 | K14: =J14*(1+'Scenarios'!K66) -> 0.052740671
A15: 乏燃料处置基金 | B15: 元/kWh | E15: =E25/'Revenue Model'!E57 -> 0.019228492 | F15: =F25/'Revenue Model'!F57 -> 0.018591932 | G15: 0.0186 | H15: 0.0186 | I15: 0.0186 | J15: 0.0186 | K15: 0.0186 | L15: 国家标准 0.026 元/kWh（投运满 5 年机组）；2025A 全机队平均 0.0186
A16: 人员费用（每千瓦核电装机） | B16: 元/kW | E16: =E27*10000/'Revenue Model'!E41 -> 255.17684 | F16: =F27*10000/'Revenue Model'!F41 -> 249.1084 | G16: =F16*(1+G18) -> 254.09057 | H16: =G16*(1+H18) -> 259.17238 | I16: =H16*(1+I18) -> 264.35583 | J16: =I16*(1+J18) -> 269.64294 | K16: =J16*(1+K18) -> 275.0358
A17: 运维及其他（每千瓦核电+新能源平均装机） | B17: 元/kW | E17: =E28*10000/('Revenue Model'!E41+('Revenue Model'!E66+'Revenue Model'!D66)/2) -> 202.36665 | F17: =F28*10000/('Revenue Model'!F41+('Revenue Model'!F66+'Revenue Model'!E66)/2) -> 162.9763 | G17: =F17*(1+G19) -> 156.45725 | H17: =G17*(1+H19) -> 156.45725 | I17: =H17*(1+I19) -> 158.02182 | J17: =I17*(1+J19) -> 159.60204 | K17: =J17*(1+K19) -> 161.19806
A18: 人员成本通胀 | B18: % | G18: 0.02 | H18: 0.02 | I18: 0.02 | J18: 0.02 | K18: 0.02
A19: 运维单位成本变动 | B19: % | G19: -0.04 | H19: 0 | I19: 0.01 | J19: 0.01 | K19: 0.01 | L19: 2025A 运维及其他 -4.62%（装机增长下仍下降，规模效应）
A20: 核电平均装机（存量+新机组加权） | B20: 万千瓦 | G20: ='Revenue Model'!G40+'Revenue Model'!G29 -> 2676.8 | H20: ='Revenue Model'!H40+'Revenue Model'!H29 -> 2961.84 | I20: ='Revenue Model'!I40+'Revenue Model'!I29 -> 3366.9 | J20: ='Revenue Model'!J40+'Revenue Model'!J29 -> 3669.4 | K20: ='Revenue Model'!K40+'Revenue Model'!K29 -> 3940.9
A21: 新能源平均装机 | B21: 万千瓦 | G21: =('Revenue Model'!F66+'Revenue Model'!G66)/2 -> 3539.1 | H21: =('Revenue Model'!G66+'Revenue Model'!H66)/2 -> 3839.1 | I21: =('Revenue Model'!H66+'Revenue Model'!I66)/2 -> 4064.1 | J21: =('Revenue Model'!I66+'Revenue Model'!J66)/2 -> 4264.1 | K21: =('Revenue Model'!J66+'Revenue Model'!K66)/2 -> 4464.1
A23: 营业成本 Cost of revenue
A24: 核燃料成本 | B24: 亿元 | C24: 85.8463 | D24: 92.1016 | E24: 75.5606 | F24: 87.0478 | G24: ='Revenue Model'!G57*G14 -> 92.318693 | H24: ='Revenue Model'!H57*H14 -> 110.40134 | I24: ='Revenue Model'!I57*I14 -> 130.51977 | J24: ='Revenue Model'!J57*J14 -> 147.93621 | K24: ='Revenue Model'!K57*K14 -> 165.23734 | L24: 2022–23A 为年报“燃料及其他材料”口径（含非核材料，乏燃料基金含于其他成本），与 2024 年后不完全可比
A25: 乏燃料处置基金 | B25: 亿元 | E25: 35.2116 | F25: 37.3339 | G25: ='Revenue Model'!G57*G15 -> 38.088187 | H25: ='Revenue Model'!H57*H15 -> 43.796728 | I25: ='Revenue Model'!I57*I15 -> 49.78635 | J25: ='Revenue Model'!J57*J15 -> 54.259418 | K25: ='Revenue Model'!K57*K15 -> 58.274088
A26: 固定资产折旧（计入成本） | B26: 亿元 | C26: 148.7413 | D26: 160.5377 | E26: 173.0367 | F26: 202.6774 | G26: ='Balance Sheet'!G76 -> 220.58518 | H26: ='Balance Sheet'!H76 -> 252.47745 | I26: ='Balance Sheet'!I76 -> 286.34412 | J26: ='Balance Sheet'!J76 -> 306.71429 | K26: ='Balance Sheet'!K76 -> 318.40202 | L26: 预测=Balance Sheet 固定资产折旧
A27: 人员费用 | B27: 亿元 | C27: 52.8459 | D27: 56.9412 | E27: 60.6045 | F27: 62.2771 | G27: =G20*G16/10000 -> 68.014963 | H27: =H20*H16/10000 -> 76.762712 | I27: =I20*I16/10000 -> 89.005963 | J27: =J20*J16/10000 -> 98.942782 | K27: =K20*K16/10000 -> 108.38886
A28: 运维及其他 | B28: 亿元 | C28: 100.1361 | D28: 105.5163 | E28: 96.7435 | F28: 92.2749 | G28: =(G20+G21)*G17/10000 -> 97.252261 | H28: =(H20+H21)*H17/10000 -> 106.40564 | I28: =(I20+I21)*I17/10000 -> 117.42602 | J28: =(J20+J21)*J17/10000 -> 126.62028 | K28: =(K20+K21)*K17/10000 -> 135.48697 | L28: 2022–23A=电厂运行维护费+其他成本（年报成本分析表）
A29: 营业成本合计 | B29: 亿元 | C29: 387.56965 | D29: 415.09673 | E29: 441.15696 | F29: 481.61107 | G29: =SUM(G24:G28) -> 516.25928 | H29: =SUM(H24:H28) -> 589.84386 | I29: =SUM(I24:I28) -> 673.08222 | J29: =SUM(J24:J28) -> 734.47298 | K29: =SUM(K24:K28) -> 785.78927 | M29: 243.92926 | N29: =IFERROR(M29/G29,"") -> 0.4724937
A30: 毛利 Gross profit | B30: 亿元 | C30: =C7-C29 -> 325.28636 | D30: =D7-D29 -> 334.47507 | E30: =E7-E29 -> 331.56363 | F30: =F7-F29 -> 339.14388 | G30: =G7-G29 -> 291.16789 | H30: =H7-H29 -> 318.87092 | I30: =I7-I29 -> 341.59168 | J30: =J7-J29 -> 361.65052 | K30: =K7-K29 -> 386.48731
A31: 毛利率 | B31: % | C31: =C30/C7 -> 0.45631426 | D31: =D30/D7 -> 0.44622152 | E31: =E30/E7 -> 0.42908606 | F31: =F30/F7 -> 0.41320967 | G31: =G30/G7 -> 0.36061195 | H31: =H30/H7 -> 0.3509032 | I31: =I30/I7 -> 0.33665168 | J31: =J30/J7 -> 0.32993593 | K31: =K30/K7 -> 0.32968953
A33: 期间费用及其他 Opex & other items
A34: 税金及附加/收入 | B34: % | C34: =C35/C7 -> 0.012235276 | D34: =D35/D7 -> 0.013763407 | E34: =E35/E7 -> 0.013934421 | F34: =F35/F7 -> 0.015066874 | G34: 0.0151 | H34: 0.0151 | I34: 0.0151 | J34: 0.0151 | K34: 0.0151
A35: 税金及附加 | B35: 亿元 | C35: 8.7219897 | D35: 10.316661 | E35: 10.767414 | F35: 12.366211 | G35: =G7*G34 -> 12.19215 | H35: =H7*H34 -> 13.721593 | I35: =I7*I34 -> 15.321576 | J35: =J7*J34 -> 16.551465 | K35: =K7*K34 -> 17.701376 | M35: 6.3786891 | N35: =IFERROR(M35/G35,"") -> 0.52317999
A36: 销售费用/收入 | B36: % | C36: =C37/C7 -> 0.0010903126 | D36: =D37/D7 -> 0.001535668 | E36: =E37/E7 -> 0.00080872319 | F36: =F37/F7 -> 0.0012144612 | G36: 0.0012 | H36: 0.0012 | I36: 0.0012 | J36: 0.0012 | K36: 0.0012
A37: 销售费用 | B37: 亿元 | C37: 0.7772359 | D37: 1.1510935 | E37: 0.62491706 | F37: 0.99677502 | G37: =G7*G36 -> 0.96891261 | H37: =H7*H36 -> 1.0904577 | I37: =I7*I36 -> 1.2176087 | J37: =J7*J36 -> 1.3153482 | K37: =K7*K36 -> 1.4067319
A38: 管理费用增速 | B38: % | G38: -0.12 | H38: 0.03 | I38: 0.03 | J38: 0.03 | K38: 0.03 | L38: 2026H1 管理费用 -14.68%（薪酬结构调整、成本管控）
A39: 管理费用 | B39: 亿元 | C39: 46.185416 | D39: 38.282356 | E39: 40.270412 | F39: 41.186341 | G39: =F39*(1+G38) -> 36.24398 | H39: =G39*(1+H38) -> 37.331299 | I39: =H39*(1+I38) -> 38.451238 | J39: =I39*(1+J38) -> 39.604775 | K39: =J39*(1+K38) -> 40.792919 | M39: 15.347234 | N39: =IFERROR(M39/G39,"") -> 0.4234423
A40: 研发费用/收入 | B40: % | C40: =C41/C7 -> 0.019610064 | D40: =D41/D7 -> 0.01846106 | E40: =E41/E7 -> 0.017788808 | F40: =F41/F7 -> 0.017540044 | G40: 0.016 | H40: 0.0175 | I40: 0.0175 | J40: 0.0175 | K40: 0.0175 | L40: 2026H1 研发 3.62 亿（研发支出下半年集中）
A41: 研发费用 | B41: 亿元 | C41: 13.979152 | D41: 13.83789 | E41: 13.745778 | F41: 14.396078 | G41: =G7*G40 -> 12.918835 | H41: =H7*H40 -> 15.902509 | I41: =I7*I40 -> 17.756793 | J41: =J7*J40 -> 19.182161 | K41: =K7*K40 -> 20.51484 | M41: 3.620268 | N41: =IFERROR(M41/G41,"") -> 0.28023177
A42: 有息负债综合利率（期初余额） | B42: % | G42: 0.023 | H42: 0.022 | I42: 0.0215 | J42: 0.0215 | K42: 0.0215 | L42: 2025A 校准：(65.40 利息费用+约 31 资本化)/期初有息负债 3,839 ≈ 2.45%；新增借款利率约 1.6–2.3%
A43: 利息资本化率（期初在建工程） | B43: % | G43: 0.013 | H43: 0.013 | I43: 0.013 | J43: 0.013 | K43: 0.013 | L43: 2025 年报：重大在建工程本期利息资本化 31.87 亿
A44: 其中：利息费用 | B44: 亿元 | C44: 76.409893 | D44: 69.337257 | E44: 67.099447 | F44: 65.398222 | G44: ='Balance Sheet'!F77*G42-'Balance Sheet'!F20*G43 -> 71.160934 | H44: ='Balance Sheet'!G77*H42-'Balance Sheet'!G20*H43 -> 72.316708 | I44: ='Balance Sheet'!H77*I42-'Balance Sheet'!H20*I43 -> 83.877339 | J44: ='Balance Sheet'!I77*J42-'Balance Sheet'!I20*J43 -> 89.676515 | K44: ='Balance Sheet'!J77*K42-'Balance Sheet'!J20*K43 -> 97.027885 | M44: 33.786572 | N44: =IFERROR(M44/G44,"") -> 0.47479101
A45: 存款利率（期初货币资金） | B45: % | G45: 0.009 | H45: 0.009 | I45: 0.009 | J45: 0.009 | K45: 0.009 | L45: 2025A 1.45/197.38≈0.7%–0.9%
...

Sheet Cash Flow
A1: 现金流量表 Cash Flow Statement（间接法；历史期取自年报补充资料与主表）
A2: 单位：亿元人民币（另有注明除外）｜蓝色=硬编码输入 黑色=公式 绿色=跨表链接｜A=实际 E=预测
A3: 项目 / Line item | B3: 单位 | C3: 2022 | D3: 2023 | E3: 2024 | F3: 2025 | G3: 2026 | H3: 2027 | I3: 2028 | J3: 2029 | K3: 2030 | L3: 来源 / 说明
A6: 经营活动 Operating activities
A7: 净利润 | B7: 亿元 | C7: 163.22859 | D7: 194.10621 | E7: 165.53095 | F7: 179.70578 | G7: ='Income Statement'!G65 -> 140.73894 | H7: ='Income Statement'!H65 -> 159.39128 | I7: ='Income Statement'!I65 -> 167.31337 | J7: ='Income Statement'!J65 -> 177.30777 | K7: ='Income Statement'!K65 -> 189.49605
A8: 固定资产折旧 | B8: 亿元 | C8: 152.0272 | D8: 160.82455 | E8: 173.32044 | F8: 203.40667 | G8: ='Balance Sheet'!G76 -> 220.58518 | H8: ='Balance Sheet'!H76 -> 252.47745 | I8: ='Balance Sheet'!I76 -> 286.34412 | J8: ='Balance Sheet'!J76 -> 306.71429 | K8: ='Balance Sheet'!K76 -> 318.40202
A9: 使用权资产、无形资产及长期待摊摊销 | B9: 亿元 | C9: =3.1243855123000004+2.1659168306+1.3656393399000002 -> 6.6559417 | D9: =2.9154197232+2.7385706627999995+1.3898663386 -> 7.0438567 | E9: =4.4977654722+3.6613896102999997+1.6161274546000002 -> 9.7752825 | F9: =5.646995999+5.0982287977+1.8744145096 -> 12.619639 | G9: 12.6 | H9: 12.6 | I9: 12.6 | J9: 12.6 | K9: 12.6 | L9: 预测期假设由等额“其他长期资产支出”补充，相关资产余额持平
A10: 资产及信用减值准备 | B10: 亿元 | C10: =-0.8726532698+2.4754308076 -> 1.6027775 | D10: =0.8373388797+2.0821847893000003 -> 2.9195237 | E10: =4.9857073546+0.6590237433 -> 5.6447311 | F10: =4.9585677513999995+0.23533976269999998 -> 5.1939075 | G10: =-('Income Statement'!G56+'Income Statement'!G55) -> 5.3 | H10: =-('Income Statement'!H56+'Income Statement'!H55) -> 5.3 | I10: =-('Income Statement'!I56+'Income Statement'!I55) -> 5.3 | J10: =-('Income Statement'!J56+'Income Statement'!J55) -> 5.3 | K10: =-('Income Statement'!K56+'Income Statement'!K55) -> 5.3
A11: 财务费用（加回，利息在筹资活动列示） | B11: 亿元 | C11: 83.465484 | D11: 74.749879 | E11: 69.842419 | F11: 69.650334 | G11: ='Income Statement'!G48 -> 73.758586 | H11: ='Income Statement'!H48 -> 75.008676 | I11: ='Income Statement'!I48 -> 86.405221 | J11: ='Income Statement'!J48 -> 92.032743 | K11: ='Income Statement'!K48 -> 99.252165
A12: 投资损失（收益以“－”填列） | B12: 亿元 | C12: -2.752364 | D12: -3.8207071 | E12: -4.1072614 | F12: -3.0864305 | G12: =-'Income Statement'!G52*(1-G13) -> -1.454715 | H12: =-'Income Statement'!H52*(1-H13) -> -1.5274507 | I12: =-'Income Statement'!I52*(1-I13) -> -1.6038233 | J12: =-'Income Statement'!J52*(1-J13) -> -1.6840144 | K12: =-'Income Statement'!K52*(1-K13) -> -1.7682151 | L12: 预测：剔除未收现的权益法收益
A13: 联营合营企业收益现金分红比例 | B13: % | G13: 0.5 | H13: 0.5 | I13: 0.5 | J13: 0.5 | K13: 0.5
A14: 存货的减少（增加以“－”） | B14: 亿元 | C14: -18.029645 | D14: -16.451731 | E14: -40.701709 | F14: -56.114369 | G14: ='Balance Sheet'!F13-'Balance Sheet'!G13 -> -37.01244 | H14: ='Balance Sheet'!G13-'Balance Sheet'!H13 -> -73.0945 | I14: ='Balance Sheet'!H13-'Balance Sheet'!I13 -> -37.1925 | J14: ='Balance Sheet'!I13-'Balance Sheet'!J13 -> -53.8675 | K14: ='Balance Sheet'!J13-'Balance Sheet'!K13 -> -17.6175
A15: 经营性应收项目的减少 | B15: 亿元 | C15: 38.297491 | D15: -26.625806 | E15: -53.904374 | F15: -8.3936219 | G15: ='Balance Sheet'!F9+'Balance Sheet'!F11-'Balance Sheet'!G9-'Balance Sheet'!G11 -> 10.715465 | H15: ='Balance Sheet'!G9+'Balance Sheet'!G11-'Balance Sheet'!H9-'Balance Sheet'!H11 -> -33.867526 | I15: ='Balance Sheet'!H9+'Balance Sheet'!H11-'Balance Sheet'!I9-'Balance Sheet'!I11 -> -35.429534 | J15: ='Balance Sheet'!I9+'Balance Sheet'!I11-'Balance Sheet'!J9-'Balance Sheet'!J11 -> -27.234292 | K15: ='Balance Sheet'!J9+'Balance Sheet'!J11-'Balance Sheet'!K9-'Balance Sheet'!K11 -> -25.463296
A16: 经营性应付项目的增加 | B16: 亿元 | C16: 40.527873 | D16: 37.387495 | E16: 81.270713 | F16: -30.025707 | G16: ='Balance Sheet'!G32+'Balance Sheet'!G34-'Balance Sheet'!F32-'Balance Sheet'!F34 -> -27.952632 | H16: ='Balance Sheet'!H32+'Balance Sheet'!H34-'Balance Sheet'!G32-'Balance Sheet'!G34 -> 22.211203 | I16: ='Balance Sheet'!I32+'Balance Sheet'!I34-'Balance Sheet'!H32-'Balance Sheet'!H34 -> 27.602426 | J16: ='Balance Sheet'!J32+'Balance Sheet'!J34-'Balance Sheet'!I32-'Balance Sheet'!I34 -> 21.165715 | K16: ='Balance Sheet'!K32+'Balance Sheet'!K34-'Balance Sheet'!J32-'Balance Sheet'!J34 -> 18.880812
A17: 其他（递延税、处置损益等） | B17: 亿元 | C17: =C18-SUM(C7:C11)-C12-C14-C15-C16 -> 1.9548267 | D17: =D18-SUM(D7:D11)-D12-D14-D15-D16 -> 1.1274806 | E17: =E18-SUM(E7:E11)-E12-E14-E15-E16 -> 0.53414032 | F17: =F18-SUM(F7:F11)-F12-F14-F15-F16 -> 1.1277717 | G17: 0 | H17: 0 | I17: 0 | J17: 0 | K17: 0
A18: 经营活动现金流量净额 CFO | B18: 亿元 | C18: 466.97817 | D18: 431.26075 | E18: 407.20533 | F18: 374.08397 | G18: =SUM(G7:G11)+G12+G14+G15+G16+G17 -> 397.27838 | H18: =SUM(H7:H11)+H12+H14+H15+H16+H17 -> 418.49913 | I18: =SUM(I7:I11)+I12+I14+I15+I16+I17 -> 511.33928 | J18: =SUM(J7:J11)+J12+J14+J15+J16+J17 -> 532.33471 | K18: =SUM(K7:K11)+K12+K14+K15+K16+K17 -> 599.08203
A20: 投资活动 Investing activities
A21: 核电基础资本开支计划（正数） | B21: 亿元 | G21: 700 | H21: 740 | I21: 780 | J21: 800 | K21: 820 | L21: 在建及核准 22 台、预算合计约 4,900 亿；2026H1 购建长期资产 346 亿（-19.5%）。牛/熊情景超支见 Scenarios
A22: 核电资本开支 | B22: 亿元 | G22: =-G21*(1+'Scenarios'!G72) -> -700 | H22: =-H21*(1+'Scenarios'!H72) -> -740 | I22: =-I21*(1+'Scenarios'!I72) -> -780 | J22: =-J21*(1+'Scenarios'!J72) -> -800 | K22: =-K21*(1+'Scenarios'!K72) -> -820
A23: 新能源单位造价 | B23: 元/kW | G23: 3400 | H23: 3400 | I23: 3400 | J23: 3400 | K23: 3400 | L23: 风光综合；含配储
A24: 新能源资本开支 | B24: 亿元 | G24: =-'Scenarios'!G54*G23/10000 -> -119 | H24: =-'Scenarios'!H54*H23/10000 -> -85 | I24: =-'Scenarios'!I54*I23/10000 -> -68 | J24: =-'Scenarios'!J54*J23/10000 -> -68 | K24: =-'Scenarios'!K54*K23/10000 -> -68
A25: 维护性资本开支（计入固定资产） | B25: 亿元 | G25: 20 | H25: 20 | I25: 20 | J25: 20 | K25: 20
A26: 维护性及其他长期资产支出 | B26: 亿元 | G26: =-(G25+G9) -> -32.6 | H26: =-(H25+H9) -> -32.6 | I26: =-(I25+I9) -> -32.6 | J26: =-(J25+J9) -> -32.6 | K26: =-(K25+K9) -> -32.6 | L26: 维护性 + 补充使用权资产/无形资产/长期待摊（使其余额持平）
A27: 购建固定资产、无形资产和其他长期资产支付的现金 | B27: 亿元 | C27: -505.09691 | D27: -671.00346 | E27: -907.08324 | F27: -936.83638 | G27: =G22+G24+G26 -> -851.6 | H27: =H22+H24+H26 -> -857.6 | I27: =I22+I24+I26 -> -880.6 | J27: =J22+J24+J26 -> -900.6 | K27: =K22+K24+K26 -> -920.6
A28: 股权投资（投资支付及取得子公司） | B28: 亿元 | C28: =-(7.609885+23.571262316) -> -31.181147 | D28: =-(16.82098266+35.5248451362) -> -52.345828 | E28: =-(10.7057562237+20.9380719869) -> -31.643828 | F28: =-(17.04755449+1.5061814588999998) -> -18.553736 | G28: -15 | H28: -15 | I28: -15 | J28: -15 | K28: -15
A29: 其他投资活动净额 | B29: 亿元 | C29: =C30-C27-C28 -> 6.1932474 | D29: =D30-D27-D28 -> 6.2339509 | E29: =E30-E27-E28 -> -10.719436 | F29: =F30-F27-F28 -> 8.6050851 | G29: 0 | H29: 0 | I29: 0 | J29: 0 | K29: 0
A30: 投资活动现金流量净额 CFI | B30: 亿元 | C30: -530.08481 | D30: -717.11534 | E30: -949.44651 | F30: -946.78503 | G30: =G27+G28+G29 -> -866.6 | H30: =H27+H28+H29 -> -872.6 | I30: =I27+I28+I29 -> -895.6 | J30: =J27+J28+J29 -> -915.6 | K30: =K27+K28+K29 -> -935.6
A32: 筹资活动 Financing activities
A33: 吸收投资（母公司层面） | B33: 亿元 | C33: =111.76312647209998-101.09238802700001 -> 10.670738 | D33: =120.3587552135-119.2940258486 -> 1.0647294 | E33: =409.34007602180003-269.34307612009997 -> 139.997 | F33: =195.24447228830002-185.24447228830002 -> 10 | G33: 0 | H33: 0 | I33: 0 | J33: 0 | K33: 0 | L33: 2024A 含 140 亿元定增（社保基金会 120 亿 + 中核集团 20 亿）
A34: 少数股东注资/资本开支 | B34: % | C34: =C35/-C27 -> 0.20014454 | D34: =D35/-D27 -> 0.17778452 | E34: =E35/-E27 -> 0.29693314 | F34: =F35/-F27 -> 0.19773407 | G34: 0.15 | H34: 0.15 | I34: 0.15 | J34: 0.15 | K34: 0.15 | L34: 合资方按持股比例出资：2024A 29.7% / 2025A 19.8%
A35: 子公司吸收少数股东投资 | B35: 亿元 | C35: 101.09239 | D35: 119.29403 | E35: 269.34308 | F35: 185.24447 | G35: =-G27*G34 -> 127.74 | H35: =-H27*H34 -> 128.64 | I35: =-I27*I34 -> 132.09 | J35: =-J27*J34 -> 135.09 | K35: =-K27*K34 -> 138.09
A36: 借款净额（取得−偿还） | B36: 亿元 | C36: =1171.6124658227-876.4772562478 -> 295.13521 | D36: =1399.874911287-923.5427706697 -> 476.33214 | E36: =1701.424257634-1140.7662032525 -> 560.65805 | F36: =1948.272447305-1371.5801507603999 -> 576.6923 | G36: =G52-('Balance Sheet'!F7+G18+G30+G33+G35+G37+G39+G40+G42+G43) -> 496.65622 | H36: =H52-('Balance Sheet'!G7+H18+H30+H33+H35+H37+H39+H40+H42+H43) -> 509.69492 | I36: =I52-('Balance Sheet'!H7+I18+I30+I33+I35+I37+I39+I40+I42+I43) -> 455.55833 | J36: =J52-('Balance Sheet'!I7+J18+J30+J33+J35+J37+J39+J40+J42+J43) -> 458.28849 | K36: =K52-('Balance Sheet'!J7+K18+K30+K33+K35+K37+K39+K40+K42+K43) -> 421.59512 | L36: 平衡项：使期末现金=目标现金
A37: 支付普通股股利 | B37: 亿元 | G37: =-'Income Statement'!F71*'Income Statement'!F77 -> -36.926247 | H37: =-'Income Statement'!G71*'Income Statement'!G77 -> -28.887182 | I37: =-'Income Statement'!H71*'Income Statement'!H77 -> -32.729563 | J37: =-'Income Statement'!I71*'Income Statement'!I77 -> -34.361515 | K37: =-'Income Statement'!J71*'Income Statement'!J77 -> -36.420361 | L37: 按上年归属普通股净利润×分红率（次年支付）
A38: 少数股东分红/少数股东损益 | B38: % | G38: 0.8 | H38: 0.8 | I38: 0.8 | J38: 0.8 | K38: 0.8 | L38: 2025A 72.87/86.66=84%
A39: 支付少数股东股利 | B39: 亿元 | C39: -56.677178 | D39: -69.007765 | E39: -69.512489 | F39: -72.86849 | G39: =-'Income Statement'!G67*G38 -> -54.606709 | H39: =-'Income Statement'!H67*H38 -> -61.843816 | I39: =-'Income Statement'!I67*I38 -> -64.917589 | J39: =-'Income Statement'!J67*J38 -> -68.795416 | K39: =-'Income Statement'!K67*K38 -> -73.524466
A40: 偿付利息（=财务费用） | B40: 亿元 | G40: =-'Income Statement'!G48 -> -73.758586 | H40: =-'Income Statement'!H48 -> -75.008676 | I40: =-'Income Statement'!I48 -> -86.405221 | J40: =-'Income Statement'!J48 -> -92.032743 | K40: =-'Income Statement'!K48 -> -99.252165
A41: 历史：分配股利、利润或偿付利息（含少数股东） | B41: 亿元 | C41: -223.1462 | D41: -202.50292 | E41: -219.37495 | F41: -209.25515 | L41: 历史期报表合并列示，预测期拆分为上面三行；本行不参与预测期合计
A42: 永续债分配 | B42: 亿元 | G42: =-'Income Statement'!G70 -> -0.2626 | H42: =-'Income Statement'!H70 -> -0.2626 | I42: =-'Income Statement'!I70 -> -0.2626 | J42: =-'Income Statement'!J70 -> -0.2626 | K42: =-'Income Statement'!K70 -> -0.2626
A43: 其他筹资活动净额 | B43: 亿元 | C43: =C44-C33-C35-C36-C41 -> -89.392652 | D43: =D44-D33-D35-D36-D41 -> -170.86728 | E43: =E44-E33-E35-E36-E41 -> -105.72688 | F43: =F44-F33-F35-F36-F41 -> -32.281557 | G43: 0 | H43: 0 | I43: 0 | J43: 0 | K43: 0
A44: 筹资活动现金流量净额 CFF | B44: 亿元 | C44: 94.359486 | D44: 223.3207 | E44: 644.89631 | F44: 530.40006 | G44: =G33+G35+G36+G37+G39+G40+G42+G43 -> 458.84208 | H44: =H33+H35+H36+H37+H39+H40+H42+H43 -> 472.33264 | I44: =I33+I35+I36+I37+I39+I40+I42+I43 -> 403.33336 | J44: =J33+J35+J36+J37+J39+J40+J42+J43 -> 397.92622 | K44: =K33+K35+K36+K37+K39+K40+K42+K43 -> 350.22553
...

Sheet Balance Sheet
A1: 资产负债表 Balance Sheet（合并口径，年末）
A2: 单位：亿元人民币（另有注明除外）｜蓝色=硬编码输入 黑色=公式 绿色=跨表链接｜A=实际 E=预测
A3: 项目 / Line item | B3: 单位 | C3: 2022 | D3: 2023 | E3: 2024 | F3: 2025 | G3: 2026 | H3: 2027 | I3: 2028 | J3: 2029 | K3: 2030 | L3: 来源 / 说明
A6: 流动资产 Current assets
A7: 货币资金 | B7: 亿元 | C7: 161.61672 | D7: 97.738191 | E7: 197.38017 | F7: 155.81643 | G7: ='Cash Flow'!G50 -> 145.33689 | H7: ='Cash Flow'!H50 -> 163.56866 | I7: ='Cash Flow'!I50 -> 182.6413 | J7: ='Cash Flow'!J50 -> 197.30223 | K7: ='Cash Flow'!K50 -> 211.00979 | L7: 预测=现金流量表期末现金（借款为平衡项）
A8: 应收账款周转天数（期末/收入×365） | B8: 天 | C8: =C9/'Income Statement'!C7*365 -> 88.124154 | D8: =D9/'Income Statement'!D7*365 -> 104.03673 | E8: =E9/'Income Statement'!E7*365 -> 116.44048 | F8: =F9/'Income Statement'!F7*365 -> 112.8379 | G8: 110 | H8: 110 | I8: 110 | J8: 110 | K8: 110 | L8: 2025A 112.8 天；含可再生能源补贴应收
A9: 应收账款 | B9: 亿元 | C9: 172.10913 | D9: 213.65205 | E9: 246.50948 | F9: 253.73224 | G9: ='Income Statement'!G7*G8/365 -> 243.33422 | H9: ='Income Statement'!H7*H8/365 -> 273.85925 | I9: ='Income Statement'!I7*I8/365 -> 305.79213 | J9: ='Income Statement'!J7*J8/365 -> 330.33859 | K9: ='Income Statement'!K7*K8/365 -> 353.28883
A10: 预付款项/收入 | B10: % | C10: =C11/'Income Statement'!C7 -> 0.039193036 | D10: =D11/'Income Statement'!D7 -> 0.064639039 | E10: =E11/'Income Statement'!E7 -> 0.035503402 | F10: =F11/'Income Statement'!F7 -> 0.032850903 | G10: 0.033 | H10: 0.033 | I10: 0.033 | J10: 0.033 | K10: 0.033
A11: 预付款项 | B11: 亿元 | C11: 27.938991 | D11: 48.451601 | E11: 27.43421 | F11: 26.962542 | G11: ='Income Statement'!G7*G10 -> 26.645097 | H11: ='Income Statement'!H7*H10 -> 29.987588 | I11: ='Income Statement'!I7*I10 -> 33.484239 | J11: ='Income Statement'!J7*J10 -> 36.172075 | K11: ='Income Statement'!K7*K10 -> 38.685127
A12: 存货/核电年末装机 | B12: 元/kW | C12: =C13*10000/'Revenue Model'!C41 -> 1044.5991 | D12: =D13*10000/'Revenue Model'!D41 -> 1112.5311 | E12: =E13*10000/'Revenue Model'!E41 -> 1299.3708 | F12: =F13*10000/'Revenue Model'!F41 -> 1452.8662 | G12: 1450 | H12: 1450 | I12: 1450 | J12: 1450 | K12: 1450 | L12: 存货主要为核燃料（含新机组首炉料）；2025A 1,453 元/kW
A13: 存货 | B13: 亿元 | C13: 248.09228 | D13: 264.22613 | E13: 308.60056 | F13: 363.21656 | G13: ='Revenue Model'!G41*G12/10000 -> 400.229 | H13: ='Revenue Model'!H41*H12/10000 -> 473.3235 | I13: ='Revenue Model'!I41*I12/10000 -> 510.516 | J13: ='Revenue Model'!J41*J12/10000 -> 564.3835 | K13: ='Revenue Model'!K41*K12/10000 -> 582.001
A14: 其他流动资产项目（票据、其他应收、合同资产、其他流动资产等） | B14: 亿元 | C14: =C64-C7-C9-C11-C13 -> 47.847053 | D14: =D64-D7-D9-D11-D13 -> 58.335359 | E14: =E64-E7-E9-E11-E13 -> 61.892359 | F14: =F64-F7-F9-F11-F13 -> 61.046516 | G14: =F14 -> 61.046516 | H14: =G14 -> 61.046516 | I14: =H14 -> 61.046516 | J14: =I14 -> 61.046516 | K14: =J14 -> 61.046516
A15: 流动资产合计 | B15: 亿元 | C15: =C7+C9+C11+C13+C14 -> 657.60417 | D15: =D7+D9+D11+D13+D14 -> 682.40333 | E15: =E7+E9+E11+E13+E14 -> 841.81678 | F15: =F7+F9+F11+F13+F14 -> 860.77428 | G15: =G7+G9+G11+G13+G14 -> 876.59172 | H15: =H7+H9+H11+H13+H14 -> 1001.7855 | I15: =I7+I9+I11+I13+I14 -> 1093.4802 | J15: =J7+J9+J11+J13+J14 -> 1189.2429 | K15: =K7+K9+K11+K13+K14 -> 1246.0313
A17: 非流动资产 Non-current assets
A18: 长期股权投资 | B18: 亿元 | C18: 56.845889 | D18: 75.799619 | E18: 84.11163 | F18: 103.85289 | G18: =F18+'Cash Flow'!G28*-1+'Income Statement'!G52*(1-'Cash Flow'!G13) -> 120.3076 | H18: =G18+'Cash Flow'!H28*-1+'Income Statement'!H52*(1-'Cash Flow'!H13) -> 136.83505 | I18: =H18+'Cash Flow'!I28*-1+'Income Statement'!I52*(1-'Cash Flow'!I13) -> 153.43887 | J18: =I18+'Cash Flow'!J28*-1+'Income Statement'!J52*(1-'Cash Flow'!J13) -> 170.12289 | K18: =J18+'Cash Flow'!K28*-1+'Income Statement'!K52*(1-'Cash Flow'!K13) -> 186.8911
A19: 固定资产 | B19: 亿元 | C19: 2690.3165 | D19: 2769.2238 | E19: 2992.3683 | F19: 3520.164 | G19: =F19+G74-G76+'Income Statement'!G56+'Income Statement'!G55 -> 3731.4144 | H19: =G19+H74-H76+'Income Statement'!H56+'Income Statement'!H55 -> 4569.3656 | I19: =H19+I74-I76+'Income Statement'!I56+'Income Statement'!I55 -> 4845.5705 | J19: =I19+J74-J76+'Income Statement'!J56+'Income Statement'!J55 -> 5239.5096 | K19: =J19+K74-K76+'Income Statement'!K56+'Income Statement'!K55 -> 5230.077 | L19: 减值（含信用减值，简化处理）冲减固定资产
A20: 在建工程 | B20: 亿元 | C20: 1015.1365 | D20: 1535.7484 | E20: 2157.6575 | F20: 2400.7903 | G20: =F20+'Cash Flow'!G22*-1-G73 -> 2810.0012 | H20: =G20+'Cash Flow'!H22*-1-H73 -> 2573.3874 | I20: =H20+'Cash Flow'!I22*-1-I73 -> 2880.7203 | J20: =I20+'Cash Flow'!J22*-1-J73 -> 3073.169 | K20: =J20+'Cash Flow'!K22*-1-K73 -> 3670.3015
A21: 使用权资产 | B21: 亿元 | C21: 36.654379 | D21: 53.931421 | E21: 75.194289 | F21: 65.056554 | G21: =F21 -> 65.056554 | H21: =G21 -> 65.056554 | I21: =H21 -> 65.056554 | J21: =I21 -> 65.056554 | K21: =J21 -> 65.056554
A22: 无形资产及开发支出 | B22: 亿元 | C22: =21.3415446971+10.1131972989 -> 31.454742 | D22: =27.3593504756+10.6744070449 -> 38.033758 | E22: =61.6184069488+12.552001311 -> 74.170408 | F22: =76.7969866952+17.0364609441 -> 93.833448 | G22: =F22 -> 93.833448 | H22: =G22 -> 93.833448 | I22: =H22 -> 93.833448 | J22: =I22 -> 93.833448 | K22: =J22 -> 93.833448
A23: 商誉 | B23: 亿元 | C23: 39.368934 | D23: 56.105702 | E23: 57.705712 | F23: 54.188855 | G23: =F23 -> 54.188855 | H23: =G23 -> 54.188855 | I23: =H23 -> 54.188855 | J23: =I23 -> 54.188855 | K23: =J23 -> 54.188855
A24: 其他非流动资产 | B24: 亿元 | C24: 85.317455 | D24: 147.57203 | E24: 278.68643 | F24: 357.6013 | G24: =F24 -> 357.6013 | H24: =G24 -> 357.6013 | I24: =H24 -> 357.6013 | J24: =I24 -> 357.6013 | K24: =J24 -> 357.6013 | L24: 含预付设备款、待抵扣进项税等
A25: 其余非流动资产项目（递延所得税资产、长期待摊、投资性房地产等） | B25: 亿元 | C25: =C65-C18-C19-C20-C21-C22-C23-C24 -> 35.813105 | D25: =D65-D18-D19-D20-D21-D22-D23-D24 -> 33.854377 | E25: =E65-E18-E19-E20-E21-E22-E23-E24 -> 35.68066 | F25: =F65-F18-F19-F20-F21-F22-F23-F24 -> 36.358254 | G25: =F25 -> 36.358254 | H25: =G25 -> 36.358254 | I25: =H25 -> 36.358254 | J25: =I25 -> 36.358254 | K25: =J25 -> 36.358254
A26: 非流动资产合计 | B26: 亿元 | C26: =SUM(C18:C25) -> 3990.9075 | D26: =SUM(D18:D25) -> 4710.2692 | E26: =SUM(E18:E25) -> 5755.5749 | F26: =SUM(F18:F25) -> 6631.8457 | G26: =SUM(G18:G25) -> 7268.7616 | H26: =SUM(H18:H25) -> 7886.6264 | I26: =SUM(I18:I25) -> 8486.7681 | J26: =SUM(J18:J25) -> 9089.8399 | K26: =SUM(K18:K25) -> 9694.3081
A27: 资产总计 Total assets | B27: 亿元 | C27: =C15+C26 -> 4648.5117 | D27: =D15+D26 -> 5392.6725 | E27: =E15+E26 -> 6597.3917 | F27: =F15+F26 -> 7492.6199 | G27: =G15+G26 -> 8145.3534 | H27: =H15+H26 -> 8888.412 | I27: =I15+I26 -> 9580.2483 | J27: =J15+J26 -> 10279.083 | K27: =K15+K26 -> 10940.339
A29: 流动负债 Current liabilities
A30: 短期借款 | B30: 亿元 | C30: 153.64517 | D30: 198.64355 | E30: 290.75734 | F30: 252.71883 | G30: =F30 -> 252.71883 | H30: =G30 -> 252.71883 | I30: =H30 -> 252.71883 | J30: =I30 -> 252.71883 | K30: =J30 -> 252.71883
A31: 应付票据及账款/(营业成本+资本开支) | B31: % | C31: =C32/('Income Statement'!C29+'Cash Flow'!C27*-1) -> 0.23008577 | D31: =D32/('Income Statement'!D29+'Cash Flow'!D27*-1) -> 0.20631221 | E31: =E32/('Income Statement'!E29+'Cash Flow'!E27*-1) -> 0.19926978 | F31: =F32/('Income Statement'!F29+'Cash Flow'!F27*-1) -> 0.20208528 | G31: 0.19 | H31: 0.19 | I31: 0.19 | J31: 0.19 | K31: 0.19 | L31: 应付账款中工程款占比高，故与成本+资本开支挂钩
A32: 应付票据及应付账款 | B32: 亿元 | C32: =1.5756649677+203.8142032266 -> 205.38987 | D32: =21.9199185291+202.1558134566 -> 224.07573 | E32: =17.843259445+250.82026161459999 -> 268.66352 | F32: =20.5764810348+266.0708726469 -> 286.64735 | G32: =('Income Statement'!G29-'Cash Flow'!G27)*G31 -> 259.89326 | H32: =('Income Statement'!H29-'Cash Flow'!H27)*H31 -> 275.01433 | I32: =('Income Statement'!I29-'Cash Flow'!I27)*I31 -> 295.19962 | J32: =('Income Statement'!J29-'Cash Flow'!J27)*J31 -> 310.66387 | K32: =('Income Statement'!K29-'Cash Flow'!K27)*K31 -> 324.21396
A33: 应交税费/收入 | B33: % | C33: =C34/'Income Statement'!C7 -> 0.054814688 | D33: =D34/'Income Statement'!D7 -> 0.056979586 | E33: =E34/'Income Statement'!E7 -> 0.091351132 | F33: =F34/'Income Statement'!F7 -> 0.070323601 | G33: 0.07 | H33: 0.07 | I33: 0.07 | J33: 0.07 | K33: 0.07
A34: 应交税费 | B34: 亿元 | C34: 39.07498 | D34: 42.710291 | E34: 70.5889 | F34: 57.718444 | G34: ='Income Statement'!G7*G33 -> 56.519902 | H34: ='Income Statement'!H7*H33 -> 63.610035 | I34: ='Income Statement'!I7*I33 -> 71.027173 | J34: ='Income Statement'!J7*J33 -> 76.728645 | K34: ='Income Statement'!K7*K33 -> 82.059361
A35: 一年内到期的非流动负债 | B35: 亿元 | C35: 234.19187 | D35: 395.08372 | E35: 313.19101 | F35: 399.54136 | G35: =F35 -> 399.54136 | H35: =G35 -> 399.54136 | I35: =H35 -> 399.54136 | J35: =I35 -> 399.54136 | K35: =J35 -> 399.54136
A36: 其他流动负债项目（合同负债、职工薪酬、其他应付款等） | B36: 亿元 | C36: =C67-C30-C32-C34-C35 -> 107.06797 | D36: =D67-D30-D32-D34-D35 -> 115.4665 | E36: =E67-E30-E32-E34-E35 -> 74.230382 | F36: =F67-F30-F32-F34-F35 -> 58.508759 | G36: =F36 -> 58.508759 | H36: =G36 -> 58.508759 | I36: =H36 -> 58.508759 | J36: =I36 -> 58.508759 | K36: =J36 -> 58.508759
A37: 流动负债合计 | B37: 亿元 | C37: =C30+C32+C34+C35+C36 -> 739.36986 | D37: =D30+D32+D34+D35+D36 -> 975.97979 | E37: =E30+E32+E34+E35+E36 -> 1017.4312 | F37: =F30+F32+F34+F35+F36 -> 1055.1347 | G37: =G30+G32+G34+G35+G36 -> 1027.1821 | H37: =H30+H32+H34+H35+H36 -> 1049.3933 | I37: =I30+I32+I34+I35+I36 -> 1076.9957 | J37: =J30+J32+J34+J35+J36 -> 1098.1615 | K37: =K30+K32+K34+K35+K36 -> 1117.0423
A39: 非流动负债 Non-current liabilities
A40: 长期借款 | B40: 亿元 | C40: 2085.1127 | D40: 2448.5336 | E40: 3043.039 | F40: 3631.7595 | G40: =F40+'Cash Flow'!G36 -> 4128.4158 | H40: =G40+'Cash Flow'!H36 -> 4638.1107 | I40: =H40+'Cash Flow'!I36 -> 5093.669 | J40: =I40+'Cash Flow'!J36 -> 5551.9575 | K40: =J40+'Cash Flow'!K36 -> 5973.5526 | L40: 平衡项：满足目标现金余额所需的净借款
A41: 应付债券 | B41: 亿元 | C41: 89.99286 | D41: 84.017267 | E41: 149.63679 | F41: 119.63885 | G41: =F41 -> 119.63885 | H41: =G41 -> 119.63885 | I41: =H41 -> 119.63885 | J41: =I41 -> 119.63885 | K41: =J41 -> 119.63885
A42: 租赁负债 | B42: 亿元 | C42: 27.897705 | D42: 36.237348 | E42: 42.079935 | F42: 47.263524 | G42: =F42 -> 47.263524 | H42: =G42 -> 47.263524 | I42: =H42 -> 47.263524 | J42: =I42 -> 47.263524 | K42: =J42 -> 47.263524
A43: 长期应付款 | B43: 亿元 | C43: 156.48043 | D43: 151.91175 | E43: 177.73875 | F43: 235.12448 | G43: =F43 -> 235.12448 | H43: =G43 -> 235.12448 | I43: =H43 -> 235.12448 | J43: =I43 -> 235.12448 | K43: =J43 -> 235.12448 | L43: 含融资租赁款、专项应付款
A44: 预计负债/核电年末装机 | B44: 元/kW | C44: =C45*10000/'Revenue Model'!C41 -> 250.59677 | D44: =D45*10000/'Revenue Model'!D41 -> 257.17046 | E44: =E45*10000/'Revenue Model'!E41 -> 266.32076 | F44: =F45*10000/'Revenue Model'!F41 -> 279.75666 | G44: 280 | H44: 280 | I44: 280 | J44: 280 | K44: 280 | L44: 核电站弃置费用；2025A 280 元/kW
A45: 预计负债（核电站弃置费用等） | B45: 亿元 | C45: 59.516733 | D45: 61.077983 | E45: 63.25118 | F45: 69.939165 | G45: ='Revenue Model'!G41*G44/10000 -> 77.2856 | H45: ='Revenue Model'!H41*H44/10000 -> 91.4004 | I45: ='Revenue Model'!I41*I44/10000 -> 98.5824 | J45: ='Revenue Model'!J41*J44/10000 -> 108.9844 | K45: ='Revenue Model'!K41*K44/10000 -> 112.3864 | L45: 增量计入固定资产（弃置成本资本化，非现金）
...

Sheet Scenarios
A1: 情景假设 Scenarios — 牛 / 基准 / 熊（切换 C4 选择器驱动全模型）
A2: 单位：亿元人民币（另有注明除外）｜蓝色=硬编码输入 黑色=公式 绿色=跨表链接｜A=实际 E=预测
A3: 项目 / Line item | B3: 单位 | C3: 2022 | D3: 2023 | E3: 2024 | F3: 2025 | G3: 2026 | H3: 2027 | I3: 2028 | J3: 2029 | K3: 2030 | L3: 来源 / 说明
A4: 情景选择器 Scenario selector（1=Bull 牛市, 2=Base 基准, 3=Bear 熊市） | C4: 2 | D4: =CHOOSE($C$4,"Bull 牛市","Base 基准","Bear 熊市") -> Base 基准
A6: 驱动因素（2026E–2030E 每年） | G6: 2026 | H6: 2027 | I6: 2028 | J6: 2029 | K6: 2030
A8: 核电综合电价（含增值税）Nuclear realized tariff incl. VAT
A9: Bull 牛市 | B9: 元/kWh | G9: 0.383 | H9: 0.385 | I9: 0.388 | J9: 0.39 | K9: 0.39
A10: Base 基准 | B10: 元/kWh | G10: 0.378 | H10: 0.376 | I10: 0.375 | J10: 0.375 | K10: 0.375
A11: Bear 熊市 | B11: 元/kWh | G11: 0.372 | H11: 0.362 | I11: 0.355 | J11: 0.35 | K11: 0.35
A12: Live 当前情景 | B12: 元/kWh | G12: =CHOOSE($C$4,G9,G10,G11) -> 0.378 | H12: =CHOOSE($C$4,H9,H10,H11) -> 0.376 | I12: =CHOOSE($C$4,I9,I10,I11) -> 0.375 | J12: =CHOOSE($C$4,J9,J10,J11) -> 0.375 | K12: =CHOOSE($C$4,K9,K10,K11) -> 0.375 | L12: 2024A 0.4151 / 2025A 0.3937（年报 售电业务经营情况）；2026H1 推算约 0.377。牛=机制电价全国推广；熊=市场化继续下行
A14: 核电存量机组平均利用小时 Nuclear fleet utilisation hours
A15: Bull 牛市 | B15: 小时 | G15: 7800 | H15: 8050 | I15: 8050 | J15: 8050 | K15: 8050
A16: Base 基准 | B16: 小时 | G16: 7650 | H16: 7950 | I16: 7950 | J16: 7950 | K16: 7950
A17: Bear 熊市 | B17: 小时 | G17: 7500 | H17: 7750 | I17: 7750 | J17: 7750 | K17: 7750
A18: Live 当前情景 | B18: 小时 | G18: =CHOOSE($C$4,G15,G16,G17) -> 7650 | H18: =CHOOSE($C$4,H15,H16,H17) -> 7950 | I18: =CHOOSE($C$4,I15,I16,I17) -> 7950 | J18: =CHOOSE($C$4,J15,J16,J17) -> 7950 | K18: =CHOOSE($C$4,K15,K16,K17) -> 7950 | L18: 2023A 7,852 / 2024A 7,710 / 2025A 8,038（年报 发电效率表）；2026H1 3,738h（大修 10 次）；公司 2026 计划核电发电 2,100 亿 kWh
A20: 新机组投产延迟（年）COD delay vs company schedule
A21: Bull 牛市 | B21: 年 | G21: 0 | H21: 0 | I21: 0 | J21: 0 | K21: 0
A22: Base 基准 | B22: 年 | G22: 0 | H22: 0 | I22: 0 | J22: 0 | K22: 0
A23: Bear 熊市 | B23: 年 | G23: 1 | H23: 1 | I23: 1 | J23: 1 | K23: 1
A24: Live 当前情景 | B24: 年 | G24: =CHOOSE($C$4,G21,G22,G23) -> 0 | H24: =CHOOSE($C$4,H21,H22,H23) -> 0 | I24: =CHOOSE($C$4,I21,I22,I23) -> 0 | J24: =CHOOSE($C$4,J21,J22,J23) -> 0 | K24: =CHOOSE($C$4,K21,K22,K23) -> 0 | L24: 公司计划商运时间见 Revenue Model 机组清单（年报 2025 第 17 页）；熊市情景整体推迟 1 年。仅 2026E 列生效
A26: 投产当年容量计入比例 COD-year capacity weight
A27: Bull 牛市 | B27: % | G27: 0.5 | H27: 0.5 | I27: 0.5 | J27: 0.5 | K27: 0.5
A28: Base 基准 | B28: % | G28: 0.4 | H28: 0.4 | I28: 0.4 | J28: 0.4 | K28: 0.4
A29: Bear 熊市 | B29: % | G29: 0.35 | H29: 0.35 | I29: 0.35 | J29: 0.35 | K29: 0.35
A30: Live 当前情景 | B30: % | G30: =CHOOSE($C$4,G27,G28,G29) -> 0.4 | H30: =CHOOSE($C$4,H27,H28,H29) -> 0.4 | I30: =CHOOSE($C$4,I27,I28,I29) -> 0.4 | J30: =CHOOSE($C$4,J27,J28,J29) -> 0.4 | K30: =CHOOSE($C$4,K27,K28,K29) -> 0.4 | L30: 新机组投产当年按此比例计入平均装机（投产月份不确定）
A32: 新能源综合电价（含增值税）Renewables realized tariff incl. VAT
A33: Bull 牛市 | B33: 元/kWh | G33: 0.36 | H33: 0.355 | I33: 0.35 | J33: 0.35 | K33: 0.35
A34: Base 基准 | B34: 元/kWh | G34: 0.355 | H34: 0.345 | I34: 0.34 | J34: 0.335 | K34: 0.335
A35: Bear 熊市 | B35: 元/kWh | G35: 0.345 | H35: 0.33 | I35: 0.32 | J35: 0.315 | K35: 0.315
A36: Live 当前情景 | B36: 元/kWh | G36: =CHOOSE($C$4,G33,G34,G35) -> 0.355 | H36: =CHOOSE($C$4,H33,H34,H35) -> 0.345 | I36: =CHOOSE($C$4,I33,I34,I35) -> 0.34 | J36: =CHOOSE($C$4,J33,J34,J35) -> 0.335 | K36: =CHOOSE($C$4,K33,K34,K35) -> 0.335 | L36: 2024A 0.4203 / 2025A 0.3732（-11.2%）；136 号文后增量项目全面入市
A38: 风电利用小时 Wind hours
A39: Bull 牛市 | B39: 小时 | G39: 1880 | H39: 1880 | I39: 1880 | J39: 1880 | K39: 1880
A40: Base 基准 | B40: 小时 | G40: 1800 | H40: 1800 | I40: 1800 | J40: 1800 | K40: 1800
A41: Bear 熊市 | B41: 小时 | G41: 1720 | H41: 1720 | I41: 1720 | J41: 1720 | K41: 1720
A42: Live 当前情景 | B42: 小时 | G42: =CHOOSE($C$4,G39,G40,G41) -> 1800 | H42: =CHOOSE($C$4,H39,H40,H41) -> 1800 | I42: =CHOOSE($C$4,I39,I40,I41) -> 1800 | J42: =CHOOSE($C$4,J39,J40,J41) -> 1800 | K42: =CHOOSE($C$4,K39,K40,K41) -> 1800 | L42: 2025A 推算约 1,928h（2024 年末风电容量按比例估算）；2026H1 风电发电量 -6.09%，弃风上升
A44: 光伏利用小时 Solar hours
A45: Bull 牛市 | B45: 小时 | G45: 1100 | H45: 1100 | I45: 1100 | J45: 1100 | K45: 1100
A46: Base 基准 | B46: 小时 | G46: 1050 | H46: 1050 | I46: 1050 | J46: 1050 | K46: 1050
A47: Bear 熊市 | B47: 小时 | G47: 1000 | H47: 1000 | I47: 1000 | J47: 1000 | K47: 1000
A48: Live 当前情景 | B48: 小时 | G48: =CHOOSE($C$4,G45,G46,G47) -> 1050 | H48: =CHOOSE($C$4,H45,H46,H47) -> 1050 | I48: =CHOOSE($C$4,I45,I46,I47) -> 1050 | J48: =CHOOSE($C$4,J45,J46,J47) -> 1050 | K48: =CHOOSE($C$4,K45,K46,K47) -> 1050 | L48: 2025A 推算约 1,126h
...

Sheet DCF Inputs
A1: DCF 输入 DCF Inputs（供 Task 3 估值使用）
A2: 单位：亿元人民币（另有注明除外）｜蓝色=硬编码输入 黑色=公式 绿色=跨表链接｜A=实际 E=预测
A3: 项目 / Line item | B3: 单位 | C3: 2022 | D3: 2023 | E3: 2024 | F3: 2025 | G3: 2026 | H3: 2027 | I3: 2028 | J3: 2029 | K3: 2030 | L3: 来源 / 说明
A6: 无杠杆自由现金流 Unlevered FCF（合并口径）
A7: 营业收入 | B7: 亿元 | C7: ='Income Statement'!C7 -> 712.85601 | D7: ='Income Statement'!D7 -> 749.5718 | E7: ='Income Statement'!E7 -> 772.72059 | F7: ='Income Statement'!F7 -> 820.75495 | G7: ='Income Statement'!G7 -> 807.42717 | H7: ='Income Statement'!H7 -> 908.71479 | I7: ='Income Statement'!I7 -> 1014.6739 | J7: ='Income Statement'!J7 -> 1096.1235 | K7: ='Income Statement'!K7 -> 1172.2766
A8: EBITDA | B8: 亿元 | C8: ='Income Statement'!C83 -> 433.82767 | D8: ='Income Statement'!D83 -> 463.52389 | E8: ='Income Statement'!E83 -> 471.24463 | F8: ='Income Statement'!F83 -> 512.50744 | G8: ='Income Statement'!G83 -> 486.2068 | H8: ='Income Statement'!H83 -> 543.58583 | I8: ='Income Statement'!I83 -> 599.05198 | J8: ='Income Statement'!J83 -> 637.95387 | K8: ='Income Statement'!K83 -> 672.625
A9: EBIT（经营口径） | B9: 亿元 | C9: ='Income Statement'!C82 -> 275.14452 | D9: ='Income Statement'!D82 -> 295.65548 | E9: ='Income Statement'!E82 -> 288.14891 | F9: ='Income Statement'!F82 -> 296.48113 | G9: ='Income Statement'!G82 -> 253.02163 | H9: ='Income Statement'!H82 -> 278.50839 | I9: ='Income Statement'!I82 -> 300.10787 | J9: ='Income Statement'!J82 -> 318.63958 | K9: ='Income Statement'!K82 -> 341.62299
A10: 税率 | B10: % | C10: ='Income Statement'!C63 -> 0.16591482 | D10: ='Income Statement'!D63 -> 0.15536802 | E10: ='Income Statement'!E63 -> 0.26639082 | F10: ='Income Statement'!F63 -> 0.22836854 | G10: ='Income Statement'!G63 -> 0.235 | H10: ='Income Statement'!H63 -> 0.235 | I10: ='Income Statement'!I63 -> 0.235 | J10: ='Income Statement'!J63 -> 0.235 | K10: ='Income Statement'!K63 -> 0.235
A11: NOPAT | B11: 亿元 | C11: =C9*(1-C10) -> 229.49397 | D11: =D9*(1-D10) -> 249.72008 | E11: =E9*(1-E10) -> 211.38868 | F11: =F9*(1-F10) -> 228.77417 | G11: =G9*(1-G10) -> 193.56154 | H11: =H9*(1-H10) -> 213.05892 | I11: =I9*(1-I10) -> 229.58252 | J11: =J9*(1-J10) -> 243.75928 | K11: =K9*(1-K10) -> 261.34158
A12: 加：折旧摊销 | B12: 亿元 | C12: ='Income Statement'!C81 -> 158.68314 | D12: ='Income Statement'!D81 -> 167.86841 | E12: ='Income Statement'!E81 -> 183.09572 | F12: ='Income Statement'!F81 -> 216.02631 | G12: ='Income Statement'!G81 -> 233.18518 | H12: ='Income Statement'!H81 -> 265.07745 | I12: ='Income Statement'!I81 -> 298.94412 | J12: ='Income Statement'!J81 -> 319.31429 | K12: ='Income Statement'!K81 -> 331.00202
A13: 减：资本开支 | B13: 亿元 | C13: ='Cash Flow'!C27 -> -505.09691 | D13: ='Cash Flow'!D27 -> -671.00346 | E13: ='Cash Flow'!E27 -> -907.08324 | F13: ='Cash Flow'!F27 -> -936.83638 | G13: ='Cash Flow'!G27 -> -851.6 | H13: ='Cash Flow'!H27 -> -857.6 | I13: ='Cash Flow'!I27 -> -880.6 | J13: ='Cash Flow'!J27 -> -900.6 | K13: ='Cash Flow'!K27 -> -920.6
A14: 减：营运资本增加 | B14: 亿元 | C14: ='Cash Flow'!C14+'Cash Flow'!C15+'Cash Flow'!C16 -> 60.795718 | D14: ='Cash Flow'!D14+'Cash Flow'!D15+'Cash Flow'!D16 -> -5.690042 | E14: ='Cash Flow'!E14+'Cash Flow'!E15+'Cash Flow'!E16 -> -13.33537 | F14: ='Cash Flow'!F14+'Cash Flow'!F15+'Cash Flow'!F16 -> -94.533699 | G14: ='Cash Flow'!G14+'Cash Flow'!G15+'Cash Flow'!G16 -> -54.249607 | H14: ='Cash Flow'!H14+'Cash Flow'!H15+'Cash Flow'!H16 -> -84.750822 | I14: ='Cash Flow'!I14+'Cash Flow'!I15+'Cash Flow'!I16 -> -45.019608 | J14: ='Cash Flow'!J14+'Cash Flow'!J15+'Cash Flow'!J16 -> -59.936077 | K14: ='Cash Flow'!K14+'Cash Flow'!K15+'Cash Flow'!K16 -> -24.199984
A15: 无杠杆自由现金流 UFCF | B15: 亿元 | C15: =C11+C12+C13+C14 -> -56.124076 | D15: =D11+D12+D13+D14 -> -259.10502 | E15: =E11+E12+E13+E14 -> -525.93421 | F15: =F11+F12+F13+F14 -> -586.5696 | G15: =G11+G12+G13+G14 -> -479.10289 | H15: =H11+H12+H13+H14 -> -464.21446 | I15: =I11+I12+I13+I14 -> -397.09297 | J15: =J11+J12+J13+J14 -> -397.46251 | K15: =K11+K12+K13+K14 -> -352.45638
A16: 少数股东损益占比（用于折算归母价值） | B16: % | C16: ='Income Statement'!C66 -> 0.44799214 | D16: ='Income Statement'!D66 -> 0.4526797 | E16: ='Income Statement'!E66 -> 0.46974617 | F16: ='Income Statement'!F66 -> 0.48225306 | G16: ='Income Statement'!G66 -> 0.485 | H16: ='Income Statement'!H66 -> 0.485 | I16: ='Income Statement'!I66 -> 0.485 | J16: ='Income Statement'!J66 -> 0.485 | K16: ='Income Statement'!K66 -> 0.485
A18: 股权价值桥 Equity bridge items（年末）
A19: 有息负债合计 | B19: 亿元 | C19: ='Balance Sheet'!C77 -> 2590.8403 | D19: ='Balance Sheet'!D77 -> 3162.5155 | E19: ='Balance Sheet'!E77 -> 3838.704 | F19: ='Balance Sheet'!F77 -> 4450.9221 | G19: ='Balance Sheet'!G77 -> 4947.5783 | H19: ='Balance Sheet'!H77 -> 5457.2733 | I19: ='Balance Sheet'!I77 -> 5912.8316 | J19: ='Balance Sheet'!J77 -> 6371.1201 | K19: ='Balance Sheet'!K77 -> 6792.7152
A20: 货币资金 | B20: 亿元 | C20: ='Balance Sheet'!C7 -> 161.61672 | D20: ='Balance Sheet'!D7 -> 97.738191 | E20: ='Balance Sheet'!E7 -> 197.38017 | F20: ='Balance Sheet'!F7 -> 155.81643 | G20: ='Balance Sheet'!G7 -> 145.33689 | H20: ='Balance Sheet'!H7 -> 163.56866 | I20: ='Balance Sheet'!I7 -> 182.6413 | J20: ='Balance Sheet'!J7 -> 197.30223 | K20: ='Balance Sheet'!K7 -> 211.00979
A21: 净负债 | B21: 亿元 | C21: ='Balance Sheet'!C78 -> 2429.2236 | D21: ='Balance Sheet'!D78 -> 3064.7773 | E21: ='Balance Sheet'!E78 -> 3641.3239 | F21: ='Balance Sheet'!F78 -> 4295.1057 | G21: ='Balance Sheet'!G78 -> 4802.2414 | H21: ='Balance Sheet'!H78 -> 5293.7046 | I21: ='Balance Sheet'!I78 -> 5730.1903 | J21: ='Balance Sheet'!J78 -> 6173.8179 | K21: ='Balance Sheet'!K78 -> 6581.7054
A22: 少数股东权益（账面） | B22: 亿元 | C22: ='Balance Sheet'!C58 -> 592.28137 | D22: ='Balance Sheet'!D58 -> 718.48379 | E22: ='Balance Sheet'!E58 -> 991.50932 | F22: ='Balance Sheet'!F58 -> 1135.0814 | G22: ='Balance Sheet'!G58 -> 1276.4731 | H22: ='Balance Sheet'!H58 -> 1420.574 | I22: ='Balance Sheet'!I58 -> 1568.8934 | J22: ='Balance Sheet'!J58 -> 1721.1823 | K22: ='Balance Sheet'!K58 -> 1877.6534
A23: 永续债 | B23: 亿元 | C23: ='Balance Sheet'!C52 -> 60 | D23: ='Balance Sheet'!D52 -> 10 | E23: ='Balance Sheet'!E52 -> 10 | F23: ='Balance Sheet'!F52 -> 10 | G23: ='Balance Sheet'!G52 -> 10 | H23: ='Balance Sheet'!H52 -> 10 | I23: ='Balance Sheet'!I52 -> 10 | J23: ='Balance Sheet'!J52 -> 10 | K23: ='Balance Sheet'!K52 -> 10
A24: 长期股权投资 | B24: 亿元 | C24: ='Balance Sheet'!C18 -> 56.845889 | D24: ='Balance Sheet'!D18 -> 75.799619 | E24: ='Balance Sheet'!E18 -> 84.11163 | F24: ='Balance Sheet'!F18 -> 103.85289 | G24: ='Balance Sheet'!G18 -> 120.3076 | H24: ='Balance Sheet'!H18 -> 136.83505 | I24: ='Balance Sheet'!I18 -> 153.43887 | J24: ='Balance Sheet'!J18 -> 170.12289 | K24: ='Balance Sheet'!K18 -> 186.8911
A25: 归母净资产 | B25: 亿元 | C25: ='Balance Sheet'!C57 -> 887.32984 | D25: ='Balance Sheet'!D57 -> 909.49624 | E25: ='Balance Sheet'!E57 -> 1102.1703 | F25: ='Balance Sheet'!F57 -> 1187.1761 | G25: ='Balance Sheet'!G57 -> 1222.4678 | H25: ='Balance Sheet'!H57 -> 1275.4045 | I25: ='Balance Sheet'!I57 -> 1328.5787 | J25: ='Balance Sheet'!J57 -> 1385.2681 | K25: ='Balance Sheet'!K57 -> 1446.1756
A26: 股本（剔除库存股） | B26: 亿股 | F26: 205.14 | G26: ='Income Statement'!G74 -> 205.14 | H26: ='Income Statement'!H74 -> 205.14 | I26: ='Income Statement'!I74 -> 205.14 | J26: ='Income Statement'!J74 -> 205.14 | K26: ='Income Statement'!K74 -> 205.14
A27: 每股归母净资产（不含永续债） | B27: 元/股 | F27: =(F25-F23)/F26 -> 5.7384033 | G27: =(G25-G23)/G26 -> 5.9104405 | H27: =(H25-H23)/H26 -> 6.1684922 | I27: =(I25-I23)/I26 -> 6.4277017 | J27: =(J25-J23)/J26 -> 6.7040465 | K27: =(K25-K23)/K26 -> 7.0009535
A29: 市场数据 Market data（2026-09-24）
A30: 股价 | B30: 元/股 | F30: 8.9 | L30: 同花顺 F10（2026-09-24 收盘），Task 1 [S18]
A31: 市值 | B31: 亿元 | F31: =F30*F26 -> 1825.746
A32: 市盈率（股价/EPS） | B32: x | F32: =$F$30/'Income Statement'!F75 -> 19.646799 | G32: =$F$30/'Income Statement'!G75 -> 25.281054 | H32: =$F$30/'Income Statement'!H75 -> 22.313112 | I32: =$F$30/'Income Statement'!I75 -> 21.253382 | J32: =$F$30/'Income Statement'!J75 -> 20.051926 | K32: =$F$30/'Income Statement'!K75 -> 18.758718
A33: 市净率 | B33: x | F33: =$F$30/F27 -> 1.5509541 | G33: =$F$30/G27 -> 1.5058099 | H33: =$F$30/H27 -> 1.4428161 | I33: =$F$30/I27 -> 1.3846318 | J33: =$F$30/J27 -> 1.3275564 | K33: =$F$30/K27 -> 1.2712554
A34: 股息率 | B34: % | G34: ='Income Statement'!G78/$F$30 -> 0.015822125 | H34: ='Income Statement'!H78/$F$30 -> 0.01792668 | I34: ='Income Statement'!I78/$F$30 -> 0.018820534 | J34: ='Income Statement'!J78/$F$30 -> 0.019948208 | K34: ='Income Statement'!K78/$F$30 -> 0.021323418
A35: EV/EBITDA（EV=市值+净负债+少数股东权益+永续债−长期股权投资） | B35: x | F35: =(F31+F21+F22+F23-F24)/F8 -> 13.974588 | G35: =($F$31+G21+G22+G23-G24)/G8 -> 16.03053 | H35: =($F$31+H21+H22+H23-H24)/H8 -> 15.477205 | I35: =($F$31+I21+I22+I23-I24)/I8 -> 14.992674 | J35: =($F$31+J21+J22+J23-J24)/J8 -> 14.986387 | K35: =($F$31+K21+K22+K23-K24)/K8 -> 15.028008
A37: 终值年指标 Terminal-year metrics（2030E）
A38: 2030E 营业收入 | B38: 亿元 | K38: ='Income Statement'!K7 -> 1172.2766
A39: 2030E EBITDA | B39: 亿元 | K39: ='Income Statement'!K83 -> 672.625
A40: 2030E EBIT | B40: 亿元 | K40: ='Income Statement'!K82 -> 341.62299
A41: 2030E UFCF | B41: 亿元 | K41: =K15 -> -352.45638
